Workbook

Sheet lab_values
A1: patient_id | B1: lactate_dehydrogenase | C1: alanine_aminotransferase | D1: hematocrit | E1: creatinine | F1: erythrocyte_mean_corpuscular_hemoglobin | G1: erythrocyte_mean_corpuscular_hemoglobin_concentration | H1: aspartate_aminotransferase | I1: erythrocyte_distribution_width | J1: erythrocyte_mean_corpuscular_volume | K1: urate | L1: leukocytes | M1: eosinophils_over_100_leukocytes | N1: hemoglobin | O1: lymphocytes_over_100_leukocytes | P1: monocytes_over_100_leukocytes | Q1: neutrophils_segmented_over_100_leukocytes | R1: platelets | S1: erythrocytes
A2: 002BD524C907A2A5121D3ADAED05D442 | B2: 750 | K2: 8.65 | L2: 33.1 | N2: 134 | R2: 157
A3: 006F52E9102A8D3BE2FE5614F42BA989 | B3: 1504 | K3: 1.2 | L3: 40.42 | N3: 7 | R3: 45
A4: 013D407166EC4FA56EB1E1F8CBE183B9
A5: 02522A2B2726FB0A03BB19F2D8D9524D | B5: 661 | C5: 14 | D5: 30.9 | E5: 0.22 | F5: 28 | G5: 33 | H5: 26 | I5: 15.2 | J5: 84 | K5: 2.3 | L5: 112.51 | M5: 0 | N5: 10.2 | O5: 19 | P5: 0 | Q5: 6 | R5: 113 | S5: 3.7
A6: 02E74F10E0327AD868D138F2B4FDD6F0
A7: 0336DCBAB05B9D5AD24F4333C7658A0E | L7: 62.7 | N7: 46 | R7: 5.4
A8: 03AFDBD66E7929B125F8597834FA83A4 | B8: 190 | C8: 6 | D8: 11.7 | E8: 0.36000001 | F8: 31 | G8: 36 | H8: 15 | I8: 12.1 | J8: 87 | K8: 2.8 | L8: 3.95 | M8: 0 | N8: 4.1999998 | O8: 84 | P8: 8 | Q8: 0 | R8: 64 | S8: 1.35
A9: 03C6B06952C750899BB03D998E631860 | L9: 7.3 | N9: 7 | R9: 48
A10: 060AD92489947D410D897474079C1477 | L10: 1.17 | N10: 7.3 | R10: 42
A11: 06138BC5AF6023646EDE0E1F7C1EAC75 | L11: 105 | N11: 55 | R11: 4.5
A12: 06409663226AF2F3114485AA4E0A23B4 | B12: 405 | K12: 4.1 | L12: 8.3 | N12: 9.1 | R12: 252
A13: 069059B7EF840F0C74A814EC9237B6EC | B13: 1073 | C13: 6 | D13: 20.4 | E13: 0.20999999 | F13: 26 | G13: 32 | H13: 34 | I13: 16.700001 | J13: 81 | K13: 3.5999999 | L13: 98.93 | M13: 0 | N13: 6.5 | O13: 40 | P13: 0 | Q13: 0 | R13: 110 | S13: 2.52
A14: 06FEE55734DEFE2EF2A60DEFFFD994FE | B14: 838 | K14: 10 | L14: 13.07 | N14: 14.8 | R14: 365
A15: 072B030BA126B2F4B2374F342BE9ED44 | B15: 659 | C15: 20 | D15: 16.1 | E15: 0.50999999 | F15: 27 | G15: 34 | H15: 34 | I15: 15 | J15: 80 | K15: 4.6999998 | L15: 70.919998 | M15: 0 | N15: 5.5 | O15: 7 | P15: 0 | Q15: 3 | R15: 118 | S15: 2.01
A16: 0777D5C17D4066B82AB86DFF8A46AF6F | B16: 380 | K16: 1.2 | L16: 0.53 | N16: 9.2 | R16: 58
A17: 07E1CD7DCA89A1678042477183B7AC3F | B17: 570 | C17: 6 | D17: 32.2 | E17: 0.3 | F17: 25 | G17: 32 | H17: 25 | I17: 14.5 | J17: 77 | K17: 7.4 | L17: 8.18 | M17: 1 | N17: 10.4 | O17: 18 | P17: 6 | Q17: 4.2 | R17: 299 | S17: 4.2
A18: 084B6FBB10729ED4DA8C3D3F5A3AE7C9 | L18: 18.7 | N18: 6.9 | R18: 30
A19: 091D584FCED301B442654DD8C23B3FC9 | L19: 102 | N19: 8 | R19: 21
A20: 093F65E080A295F8076B1C5722A46AA2 | B20: 515 | C20: 7 | D20: 13 | E20: 0.33000001 | F20: 31 | G20: 31 | H20: 22 | I20: 20.299999 | J20: 99 | K20: 4.6999998 | L20: 29.27 | M20: 0 | N20: 4 | O20: 32 | P20: 0 | Q20: 0 | R20: 17 | S20: 1.3099999
A21: 0A09C8844BA8F0936C20BD791130D6B6 | B21: 172 | K21: 5.1 | L21: 1.6 | N21: 12.7 | R21: 205
A22: 0AA1883C6411F7873CB83DACB17B0AFC | L22: 54.7 | N22: 9.7 | R22: 16
A23: 0F28B5D49B3020AFEECD95B4009ADF4C | B23: 268 | C23: 16 | D23: 15.9 | E23: 0.94 | F23: 32 | G23: 35 | H23: 19 | I23: 17.5 | J23: 96 | K23: 4.5 | L23: 1.3 | M23: 2 | N23: 5.5 | O23: 36 | P23: 20 | Q23: 4 | R23: 34 | S23: 1.66
A24: 12ED127BACFF11D62A255BE81C5E2310 | B24: 543 | K24: 3.88 | L24: 13.83 | N24: 106 | R24: 209
A25: 12F54ACB6F92C80EAC9609D202A98325 | B25: 1198 | K25: 9 | L25: 17.43 | N25: 10.6 | R25: 30
A26: 1385974ED5904A438616FF7BDB3F7439 | B26: 982 | C26: 8 | D26: 24.8 | E26: 0.63 | F26: 34 | G26: 33 | H26: 19 | I26: 16.8 | J26: 103 | K26: 3.5 | L26: 134.43 | M26: 0 | N26: 8.1 | O26: 2 | P26: 0 | Q26: 2 | R26: 173 | S26: 2.4
A27: 140F6969D5213FD0ECE03148E62E461E | B27: 705 | K27: 5.1 | L27: 218.2 | N27: 6.7 | R27: 5
A28: 149E9677A5989FD342AE44213DF68868 | B28: 3030 | K28: 2.3 | L28: 16.23 | N28: 11.1 | R28: 190
A29: 14BFA6BB14875E45BBA028A21ED38046 | B29: 441 | C29: 57 | D29: 12 | E29: 0.30000001 | F29: 30 | G29: 33 | H29: 46 | I29: 15.9 | J29: 93 | K29: 5.3000002 | L29: 5.9499998 | M29: 1 | N29: 3.9000001 | O29: 79 | P29: 0 | Q29: 2 | R29: 6 | S29: 1.29
A30: 1679091C5A880FAF6FB5E6087EB1B2DC | B30: 915 | C30: 18 | D30: 33 | E30: 0.97 | F30: 30.2 | G30: 33.3 | H30: 46 | I30: 15.6 | J30: 90.5 | K30: 9.2 | L30: 162.1 | M30: 0.8 | N30: 11.4 | O30: 5.6 | P30: 3 | Q30: 66 | R30: 602 | S30: 3.72
A31: 17E62166FC8586DFA4D1BC0E1742C08B | B31: 595 | C31: 10 | D31: 26 | E31: 0.61 | F31: 28.7 | G31: 32.9 | H31: 26 | J31: 87.2 | K31: 4.8 | L31: 271.8 | M31: 6 | N31: 8.5 | O31: 8 | P31: 6 | Q31: 23 | R31: 580 | S31: 3
A32: 182BE0C5CDCD5072BB1864CDEE4D3D6E | D32: 20 | F32: 29.8 | G32: 34 | I32: 18.7 | J32: 86 | L32: 358.9 | M32: 8 | N32: 6.29 | O32: 0 | P32: 4 | Q32: 25 | R32: 1299 | S32: 2.32
A33: 19CA14E7EA6328A42E0EB13D585E4C22 | D33: 19.1 | F33: 31.8 | G33: 36.1 | I33: 19.6 | J33: 88 | L33: 293.9 | M33: 3 | N33: 8.9 | O33: 3 | P33: 1 | Q33: 46 | R33: 618 | S33: 2.17
A34: 1A00B3B296CD48BA5D1BD76B18C48346 | B34: 402 | K34: 4.3 | L34: 24.6 | N34: 8.8 | R34: 317
A35: 1AFA34A7F984EEABDBB0A7D494132EE5 | B35: 338 | C35: 12 | D35: 21.4 | E35: 0.44 | F35: 32 | G35: 36 | H35: 21 | I35: 16.5 | J35: 93 | K35: 3 | L35: 2.25 | M35: 5 | N35: 6.6999998 | O35: 66 | P35: 1 | Q35: 8 | R35: 22 | S35: 2.3
A36: 1C383CD30B7C298AB50293ADFECB7B18 | D36: 46 | F36: 29 | G36: 33.4 | J36: 87 | L36: 52.42 | M36: 1 | N36: 15.3 | O36: 5 | Q36: 64 | R36: 363 | S36: 5.27
A37: 1C9AC0159C94D8D0CBEDC973445AF2DA | B37: 848 | K37: 0.4 | L37: 36.43 | N37: 7 | R37: 35
A38: 1F0E3DAD99908345F7439F8FFABDFFC4 | B38: 979 | C38: 12 | D38: 18.7 | E38: 0.39 | F38: 32.5 | G38: 35.3 | I38: 19 | J38: 92.1 | K38: 4.49 | L38: 514.3 | M38: 2 | N38: 6.6 | O38: 4 | P38: 0 | Q38: 35 | R38: 352 | S38: 2.03
A39: 202CB962AC59075B964B07152D234B70 | B39: 422 | C39: 5 | D39: 25.7 | E39: 0.44 | F39: 33 | G39: 37 | H39: 17 | I39: 19.8 | J39: 91 | K39: 4.5 | L39: 30.4 | M39: 0 | N39: 9.4 | O39: 9 | P39: 1 | Q39: 7 | R39: 65 | S39: 2.82
A40: 26657D5FF9020D2ABEFE558796B99584 | B40: 479 | C40: 8 | D40: 25 | E40: 0.22 | F40: 25 | G40: 32 | H40: 32 | I40: 16.299999 | J40: 78 | K40: 2.7 | L40: 12.24 | M40: 0 | N40: 8 | O40: 22 | P40: 3 | Q40: 14 | R40: 194 | S40: 3.22
...

Sheet idc_dictionary
A1: column_formula | B1: column_label_formula
A2: lactate_dehydrogenase | B2: LOINC:14804-9 COMPONENT: Lactate dehydrogenase DISPLAY_NAME: LDH Lactate to pyruvate reaction
A3: alanine_aminotransferase | B3: LOINC:1743-4 COMPONENT: Alanine aminotransferase DISPLAY_NAME: ALT With P-5'-P [Catalytic activity/Vol]
A4: hematocrit | B4: LOINC:20570-8 COMPONENT: Hematocrit DISPLAY_NAME: Hematocrit (Bld) [Volume fraction]
A5: creatinine | B5: LOINC:2160-0 COMPONENT: Creatinine DISPLAY_NAME: Creatinine [Mass/Vol]
A6: erythrocyte_mean_corpuscular_hemoglobin | B6: LOINC:28539-5 COMPONENT: Erythrocyte mean corpuscular hemoglobin DISPLAY_NAME: MCH (RBC) [Entitic mass]
A7: erythrocyte_mean_corpuscular_hemoglobin_concentration | B7: LOINC:28540-3 COMPONENT: Erythrocyte mean corpuscular hemoglobin concentration DISPLAY_NAME: MCHC (RBC) [Mass/Vol]
A8: aspartate_aminotransferase | B8: LOINC:30239-8 COMPONENT: Aspartate aminotransferase DISPLAY_NAME: AST With P-5'-P [Catalytic activity/Vol]
A9: erythrocyte_distribution_width | B9: LOINC:30385-9 COMPONENT: Erythrocyte distribution width DISPLAY_NAME: Erythrocyte distribution width (RBC) [Ratio]
A10: erythrocyte_mean_corpuscular_volume | B10: LOINC:30428-7 COMPONENT: Erythrocyte mean corpuscular volume DISPLAY_NAME: MCV (RBC) [Entitic vol]
A11: urate | B11: LOINC:3084-1 COMPONENT: Urate DISPLAY_NAME: Urate [Mass/Vol]
A12: leukocytes | B12: LOINC:6690-2 COMPONENT: Leukocytes DISPLAY_NAME: WBC Auto (Bld) [#/Vol]
... A19: erythrocytes | B19: LOINC:789-8 COMPONENT: Erythrocytes DISPLAY_NAME: RBC Auto (Bld) [#/Vol]

Sheet idc_dictionary_formula
A1: column_formula | B1: column_label_formula
A2: =IFERROR(__xludf.DUMMYFUNCTION("REGEXREPLACE(REGEXREPLACE(LOWER(original_dictionary!B2),""[ .]"",""_""),""/"",""_over_"")"),"lactate_dehydrogenase") -> lactate_dehydrogenase | B2: =concat("LOINC:",concat(original_dictionary!A2,concat(" COMPONENT: ",concat(original_dictionary!B2,concat(" DISPLAY_NAME: ",original_dictionary!C2))))) -> LOINC:14804-9 COMPONENT: Lactate dehydrogenase DISPLAY_NAME: LDH Lactate to pyruvate reaction
A3: =IFERROR(__xludf.DUMMYFUNCTION("REGEXREPLACE(REGEXREPLACE(LOWER(original_dictionary!B3),""[ .]"",""_""),""/"",""_over_"")"),"alanine_aminotransferase") -> alanine_aminotransferase | B3: =concat("LOINC:",concat(original_dictionary!A3,concat(" COMPONENT: ",concat(original_dictionary!B3,concat(" DISPLAY_NAME: ",original_dictionary!C3))))) -> LOINC:1743-4 COMPONENT: Alanine aminotransferase DISPLAY_NAME: ALT With P-5'-P [Catalytic activity/Vol]
A4: =IFERROR(__xludf.DUMMYFUNCTION("REGEXREPLACE(REGEXREPLACE(LOWER(original_dictionary!B4),""[ .]"",""_""),""/"",""_over_"")"),"hematocrit") -> hematocrit | B4: =concat("LOINC:",concat(original_dictionary!A4,concat(" COMPONENT: ",concat(original_dictionary!B4,concat(" DISPLAY_NAME: ",original_dictionary!C4))))) -> LOINC:20570-8 COMPONENT: Hematocrit DISPLAY_NAME: Hematocrit (Bld) [Volume fraction]
A5: =IFERROR(__xludf.DUMMYFUNCTION("REGEXREPLACE(REGEXREPLACE(LOWER(original_dictionary!B5),""[ .]"",""_""),""/"",""_over_"")"),"creatinine") -> creatinine | B5: =concat("LOINC:",concat(original_dictionary!A5,concat(" COMPONENT: ",concat(original_dictionary!B5,concat(" DISPLAY_NAME: ",original_dictionary!C5))))) -> LOINC:2160-0 COMPONENT: Creatinine DISPLAY_NAME: Creatinine [Mass/Vol]
A6: =IFERROR(__xludf.DUMMYFUNCTION("REGEXREPLACE(REGEXREPLACE(LOWER(original_dictionary!B6),""[ .]"",""_""),""/"",""_over_"")"),"erythrocyte_mean_corpuscular_hemoglobin") -> erythrocyte_mean_corpuscular_hemoglobin | B6: =concat("LOINC:",concat(original_dictionary!A6,concat(" COMPONENT: ",concat(original_dictionary!B6,concat(" DISPLAY_NAME: ",original_dictionary!C6))))) -> LOINC:28539-5 COMPONENT: Erythrocyte mean corpuscular hemoglobin DISPLAY_NAME: MCH (RBC) [Entitic mass]
A7: =IFERROR(__xludf.DUMMYFUNCTION("REGEXREPLACE(REGEXREPLACE(LOWER(original_dictionary!B7),""[ .]"",""_""),""/"",""_over_"")"),"erythrocyte_mean_corpuscular_hemoglobin_concentration") -> erythrocyte_mean_corpuscular_hemoglobin_concentration | B7: =concat("LOINC:",concat(original_dictionary!A7,concat(" COMPONENT: ",concat(original_dictionary!B7,concat(" DISPLAY_NAME: ",original_dictionary!C7))))) -> LOINC:28540-3 COMPONENT: Erythrocyte mean corpuscular hemoglobin concentration DISPLAY_NAME: MCHC (RBC) [Mass/Vol]
A8: =IFERROR(__xludf.DUMMYFUNCTION("REGEXREPLACE(REGEXREPLACE(LOWER(original_dictionary!B8),""[ .]"",""_""),""/"",""_over_"")"),"aspartate_aminotransferase") -> aspartate_aminotransferase | B8: =concat("LOINC:",concat(original_dictionary!A8,concat(" COMPONENT: ",concat(original_dictionary!B8,concat(" DISPLAY_NAME: ",original_dictionary!C8))))) -> LOINC:30239-8 COMPONENT: Aspartate aminotransferase DISPLAY_NAME: AST With P-5'-P [Catalytic activity/Vol]
A9: =IFERROR(__xludf.DUMMYFUNCTION("REGEXREPLACE(REGEXREPLACE(LOWER(original_dictionary!B9),""[ .]"",""_""),""/"",""_over_"")"),"erythrocyte_distribution_width") -> erythrocyte_distribution_width | B9: =concat("LOINC:",concat(original_dictionary!A9,concat(" COMPONENT: ",concat(original_dictionary!B9,concat(" DISPLAY_NAME: ",original_dictionary!C9))))) -> LOINC:30385-9 COMPONENT: Erythrocyte distribution width DISPLAY_NAME: Erythrocyte distribution width (RBC) [Ratio]
A10: =IFERROR(__xludf.DUMMYFUNCTION("REGEXREPLACE(REGEXREPLACE(LOWER(original_dictionary!B10),""[ .]"",""_""),""/"",""_over_"")"),"erythrocyte_mean_corpuscular_volume") -> erythrocyte_mean_corpuscular_volume | B10: =concat("LOINC:",concat(original_dictionary!A10,concat(" COMPONENT: ",concat(original_dictionary!B10,concat(" DISPLAY_NAME: ",original_dictionary!C10))))) -> LOINC:30428-7 COMPONENT: Erythrocyte mean corpuscular volume DISPLAY_NAME: MCV (RBC) [Entitic vol]
A11: =IFERROR(__xludf.DUMMYFUNCTION("REGEXREPLACE(REGEXREPLACE(LOWER(original_dictionary!B11),""[ .]"",""_""),""/"",""_over_"")"),"urate") -> urate | B11: =concat("LOINC:",concat(original_dictionary!A11,concat(" COMPONENT: ",concat(original_dictionary!B11,concat(" DISPLAY_NAME: ",original_dictionary!C11))))) -> LOINC:3084-1 COMPONENT: Urate DISPLAY_NAME: Urate [Mass/Vol]
A12: =IFERROR(__xludf.DUMMYFUNCTION("REGEXREPLACE(REGEXREPLACE(LOWER(original_dictionary!B12),""[ .]"",""_""),""/"",""_over_"")"),"leukocytes") -> leukocytes | B12: =concat("LOINC:",concat(original_dictionary!A12,concat(" COMPONENT: ",concat(original_dictionary!B12,concat(" DISPLAY_NAME: ",original_dictionary!C12))))) -> LOINC:6690-2 COMPONENT: Leukocytes DISPLAY_NAME: WBC Auto (Bld) [#/Vol]
A13: =IFERROR(__xludf.DUMMYFUNCTION("REGEXREPLACE(REGEXREPLACE(LOWER(original_dictionary!B13),""[ .]"",""_""),""/"",""_over_"")"),"eosinophils_over_100_leukocytes") -> eosinophils_over_100_leukocytes | B13: =concat("LOINC:",concat(original_dictionary!A13,concat(" COMPONENT: ",concat(original_dictionary!B13,concat(" DISPLAY_NAME: ",original_dictionary!C13))))) -> LOINC:714-6 COMPONENT: Eosinophils/100 leukocytes DISPLAY_NAME: Eosinophils/100 WBC Manual cnt (Bld)
A14: =IFERROR(__xludf.DUMMYFUNCTION("REGEXREPLACE(REGEXREPLACE(LOWER(original_dictionary!B14),""[ .]"",""_""),""/"",""_over_"")"),"hemoglobin") -> hemoglobin | B14: =concat("LOINC:",concat(original_dictionary!A14,concat(" COMPONENT: ",concat(original_dictionary!B14,concat(" DISPLAY_NAME: ",original_dictionary!C14))))) -> LOINC:718-7 COMPONENT: Hemoglobin DISPLAY_NAME: Hemoglobin (Bld) [Mass/Vol]
A15: =IFERROR(__xludf.DUMMYFUNCTION("REGEXREPLACE(REGEXREPLACE(LOWER(original_dictionary!B15),""[ .]"",""_""),""/"",""_over_"")"),"lymphocytes_over_100_leukocytes") -> lymphocytes_over_100_leukocytes | B15: =concat("LOINC:",concat(original_dictionary!A15,concat(" COMPONENT: ",concat(original_dictionary!B15,concat(" DISPLAY_NAME: ",original_dictionary!C15))))) -> LOINC:737-7 COMPONENT: Lymphocytes/100 leukocytes DISPLAY_NAME: Lymphocytes/100 WBC Manual cnt (Bld)
A16: =IFERROR(__xludf.DUMMYFUNCTION("REGEXREPLACE(REGEXREPLACE(LOWER(original_dictionary!B16),""[ .]"",""_""),""/"",""_over_"")"),"monocytes_over_100_leukocytes") -> monocytes_over_100_leukocytes | B16: =concat("LOINC:",concat(original_dictionary!A16,concat(" COMPONENT: ",concat(original_dictionary!B16,concat(" DISPLAY_NAME: ",original_dictionary!C16))))) -> LOINC:744-3 COMPONENT: Monocytes/100 leukocytes DISPLAY_NAME: Monocytes/100 WBC Manual cnt (Bld)
A17: =IFERROR(__xludf.DUMMYFUNCTION("REGEXREPLACE(REGEXREPLACE(LOWER(original_dictionary!B17),""[ .]"",""_""),""/"",""_over_"")"),"neutrophils_segmented_over_100_leukocytes") -> neutrophils_segmented_over_100_leukocytes | B17: =concat("LOINC:",concat(original_dictionary!A17,concat(" COMPONENT: ",concat(original_dictionary!B17,concat(" DISPLAY_NAME: ",original_dictionary!C17))))) -> LOINC:769-0 COMPONENT: Neutrophils.segmented/100 leukocytes DISPLAY_NAME: Segmented neutrophils/100 WBC Manual cnt (Bld)
A18: =IFERROR(__xludf.DUMMYFUNCTION("REGEXREPLACE(REGEXREPLACE(LOWER(original_dictionary!B18),""[ .]"",""_""),""/"",""_over_"")"),"platelets") -> platelets | B18: =concat("LOINC:",concat(original_dictionary!A18,concat(" COMPONENT: ",concat(original_dictionary!B18,concat(" DISPLAY_NAME: ",original_dictionary!C18))))) -> LOINC:777-3 COMPONENT: Platelets DISPLAY_NAME: Platelets Auto (Bld) [#/Vol]
A19: =IFERROR(__xludf.DUMMYFUNCTION("REGEXREPLACE(REGEXREPLACE(LOWER(original_dictionary!B19),""[ .]"",""_""),""/"",""_over_"")"),"erythrocytes") -> erythrocytes | B19: =concat("LOINC:",concat(original_dictionary!A19,concat(" COMPONENT: ",concat(original_dictionary!B19,concat(" DISPLAY_NAME: ",original_dictionary!C19))))) -> LOINC:789-8 COMPONENT: Erythrocytes DISPLAY_NAME: RBC Auto (Bld) [#/Vol]

Sheet original_dictionary
A1: LOINC | B1: COMPONENT | C1: DISPLAY_NAME
A2: 14804-9 | B2: Lactate dehydrogenase | C2: LDH Lactate to pyruvate reaction
A3: 1743-4 | B3: Alanine aminotransferase | C3: ALT With P-5'-P [Catalytic activity/Vol]
A4: 20570-8 | B4: Hematocrit | C4: Hematocrit (Bld) [Volume fraction]
A5: 2160-0 | B5: Creatinine | C5: Creatinine [Mass/Vol]
A6: 28539-5 | B6: Erythrocyte mean corpuscular hemoglobin | C6: MCH (RBC) [Entitic mass]
A7: 28540-3 | B7: Erythrocyte mean corpuscular hemoglobin concentration | C7: MCHC (RBC) [Mass/Vol]
A8: 30239-8 | B8: Aspartate aminotransferase | C8: AST With P-5'-P [Catalytic activity/Vol]
A9: 30385-9 | B9: Erythrocyte distribution width | C9: Erythrocyte distribution width (RBC) [Ratio]
A10: 30428-7 | B10: Erythrocyte mean corpuscular volume | C10: MCV (RBC) [Entitic vol]
A11: 3084-1 | B11: Urate | C11: Urate [Mass/Vol]
A12: 6690-2 | B12: Leukocytes | C12: WBC Auto (Bld) [#/Vol]
... A19: 789-8 | B19: Erythrocytes | C19: RBC Auto (Bld) [#/Vol]
A21: Supplemental Table 2: List of laboratory values in the dataset as LOINC codes with their respective descriptions.
